<robot name="DJI Mini 3 Pro">
  <link name="base_link"/>

  <joint name="body_joint" type="fixed">
    <parent link="base_link"/>
    <child  link="body_link"/>
    <origin xyz="0 0 0" rpy="0 -0.2495821 0"/>
  </joint>

  <link name="body_link">
    <visual>
      <geometry>
        <mesh filename="package://dji_drone_description/meshes/mini3pro/body.dae" />
      </geometry>
      <origin xyz="0 0 0" rpy="0 0 0"/>
    </visual>
  </link>

  <joint name="pitch_joint" type="revolute">
    <parent link="body_link"/>
    <child  link="gimbal_0_link"/>
    <origin xyz="0.031301 0 0.016852" rpy="0 0.2495821 0"/>
    <axis xyz="0 1 0"/>
    <limit lower="-2.356194" upper="1.396263" effort="0" velocity="0"/>
  </joint>

  <link name="gimbal_0_link">
    <visual>
      <geometry>
        <mesh filename="package://dji_drone_description/meshes/mini3pro/gimbal_0.dae" />
      </geometry>
      <origin xyz="0 0 0" rpy="0 0 0"/>
    </visual>
  </link>

  <joint name="yaw_joint" type="revolute">
    <parent link="gimbal_0_link"/>
    <child  link="gimbal_1_link"/>
    <origin xyz="-0.004329 -0.00045 -0.012159" rpy="0 0 0"/>
    <axis xyz="0.360035 0 0.932939"/>
    <limit lower="-0.523599" upper="0.523599" effort="0" velocity="0"/>
  </joint>

  <link name="gimbal_1_link">
    <visual>
      <geometry>
        <mesh filename="package://dji_drone_description/meshes/mini3pro/gimbal_1.dae" />
      </geometry>
      <origin xyz="0 0 0" rpy="0 0 0"/>
    </visual>
  </link>

  <joint name="roll_joint" type="revolute">
    <parent link="gimbal_1_link"/>
    <child  link="camera_link"/>
    <origin xyz="0.000056 -0.000012 0.018293" rpy="0 0 0"/>
    <axis xyz="1 0 0"/>
    <limit lower="-2.356194" upper="0.785398" effort="0" velocity="0"/>
  </joint>

  <link name="camera_link">
    <visual>
      <geometry>
        <mesh filename="package://dji_drone_description/meshes/mini3pro/camera.dae" />
      </geometry>
      <origin xyz="0 0 0" rpy="0 0 0"/>
    </visual>
  </link>

  <joint name="motor_lf_joint" type="continuous">
    <parent link="body_link"/>
    <child  link="motor_lf_link"/>
    <origin xyz="0.03567 0.112728 0.020459" rpy="0 0 0"/>
    <axis xyz="-0.229562 -0.131032 -0.964434"/>
  </joint>  

    <link name="motor_lf_link">
    <visual>
      <geometry>
        <mesh filename="package://dji_drone_description/meshes/mini3pro/motor_lf.dae" />
      </geometry>
      <origin xyz="0 0 0" rpy="0 0 0"/>
    </visual>
  </link>

  <joint name="motor_rf_joint" type="continuous">
    <parent link="body_link"/>
    <child  link="motor_rf_link"/>
    <origin xyz="0.03567 -0.113628 0.020459" rpy="0 0 0"/>
    <axis xyz="0.229562 -0.131032 0.964434"/>
  </joint>  

  <link name="motor_rf_link">
    <visual>
      <geometry>
        <mesh filename="package://dji_drone_description/meshes/mini3pro/motor_rf.dae" />
      </geometry>
      <origin xyz="0 0 0" rpy="0 0 0"/>
    </visual>
  </link>

  <joint name="motor_lb_joint" type="continuous">
    <parent link="body_link"/>
    <child  link="motor_lb_link"/>
    <origin xyz="-0.115162 0.080307 0.045549" rpy="0 0 0"/>s
    <axis xyz="0.235748 0.119758 0.964407"/>
  </joint>  

  <link name="motor_lb_link">
    <visual>
      <geometry>
        <mesh filename="package://dji_drone_description/meshes/mini3pro/motor_lb.dae" />
      </geometry>
      <origin xyz="0 0 0" rpy="0 0 0"/>
    </visual>
  </link>

  <joint name="motor_rb_joint" type="continuous">
    <parent link="body_link"/>
    <child  link="motor_rb_link"/>
    <origin xyz="-0.115162 -0.081207 0.045549" rpy="0 0 0"/>
    <axis xyz="-0.235819 0.119797 -0.964385"/>
  </joint>  

    <link name="motor_rb_link">
    <visual>
      <geometry>
        <mesh filename="package://dji_drone_description/meshes/mini3pro/motor_rb.dae" />
      </geometry>
      <origin xyz="0 0 0" rpy="0 0 0"/>
    </visual>
  </link>
</robot>
